E:\Anaconda3\envs\tf2\python.exe "D:\PyCharm 2020.1.3\plugins\python\helpers\pydev\pydevconsole.py" --mode=client --port=49448
import sys; print('Python %s on %s' % (sys.version, sys.platform))
sys.path.extend(['E:\\python_workfile\\a', 'E:/python_workfile/a'])
Python 3.8.5 | packaged by conda-forge | (default, Sep 16 2020, 17:19:16) [MSC v.1916 64 bit (AMD64)]
Type 'copyright', 'credits' or 'license' for more information
IPython 7.18.1 -- An enhanced Interactive Python. Type '?' for help.
PyDev console: using IPython 7.18.1
Python 3.8.5 | packaged by conda-forge | (default, Sep 16 2020, 17:19:16) [MSC v.1916 64 bit (AMD64)] on win32
import hhaa as ha
   lons  lats  swch
0   100    80    90
1    10    20    95
2     1     1    96
ha.df[:,2]
Traceback (most recent call last):
  File "E:\Anaconda3\envs\tf2\lib\site-packages\IPython\core\interactiveshell.py", line 3417, in run_code
    exec(code_obj, self.user_global_ns, self.user_ns)
  File "<ipython-input-3-2f0fba5e1351>", line 1, in <module>
    ha.df[:,2]
  File "E:\Anaconda3\envs\tf2\lib\site-packages\pandas\core\frame.py", line 2902, in __getitem__
    indexer = self.columns.get_loc(key)
  File "E:\Anaconda3\envs\tf2\lib\site-packages\pandas\core\indexes\base.py", line 2891, in get_loc
    return self._engine.get_loc(casted_key)
  File "pandas\_libs\index.pyx", line 70, in pandas._libs.index.IndexEngine.get_loc
  File "pandas\_libs\index.pyx", line 75, in pandas._libs.index.IndexEngine.get_loc
TypeError: '(slice(None, None, None), 2)' is an invalid key
ha.df[:2]
Out[4]:
   lons  lats  swch
0   100    80    90
1    10    20    95
ha.df[,:2]
  File "<ipython-input-5-0e6787804e72>", line 1
    ha.df[,:2]
          ^
SyntaxError: invalid syntax
ha.df[:,:2]
Traceback (most recent call last):
  File "E:\Anaconda3\envs\tf2\lib\site-packages\IPython\core\interactiveshell.py", line 3417, in run_code
    exec(code_obj, self.user_global_ns, self.user_ns)
  File "<ipython-input-6-7786c71ebb2c>", line 1, in <module>
    ha.df[:,:2]
  File "E:\Anaconda3\envs\tf2\lib\site-packages\pandas\core\frame.py", line 2902, in __getitem__
    indexer = self.columns.get_loc(key)
  File "E:\Anaconda3\envs\tf2\lib\site-packages\pandas\core\indexes\base.py", line 2891, in get_loc
    return self._engine.get_loc(casted_key)
  File "pandas\_libs\index.pyx", line 70, in pandas._libs.index.IndexEngine.get_loc
  File "pandas\_libs\index.pyx", line 75, in pandas._libs.index.IndexEngine.get_loc
TypeError: '(slice(None, None, None), slice(None, 2, None))' is an invalid key
ha.df[:,:]
Traceback (most recent call last):
  File "E:\Anaconda3\envs\tf2\lib\site-packages\IPython\core\interactiveshell.py", line 3417, in run_code
    exec(code_obj, self.user_global_ns, self.user_ns)
  File "<ipython-input-7-1b5ac98a28f6>", line 1, in <module>
    ha.df[:,:]
  File "E:\Anaconda3\envs\tf2\lib\site-packages\pandas\core\frame.py", line 2902, in __getitem__
    indexer = self.columns.get_loc(key)
  File "E:\Anaconda3\envs\tf2\lib\site-packages\pandas\core\indexes\base.py", line 2891, in get_loc
    return self._engine.get_loc(casted_key)
  File "pandas\_libs\index.pyx", line 70, in pandas._libs.index.IndexEngine.get_loc
  File "pandas\_libs\index.pyx", line 75, in pandas._libs.index.IndexEngine.get_loc
TypeError: '(slice(None, None, None), slice(None, None, None))' is an invalid key
ha.df[::2]
Out[8]:
   lons  lats  swch
0   100    80    90
2     1     1    96
ha.df[::]
Out[9]:
   lons  lats  swch
0   100    80    90
1    10    20    95
2     1     1    96
ha.df[::1]
Out[10]:
   lons  lats  swch
0   100    80    90
1    10    20    95
2     1     1    96
ha.df[::3]
Out[11]:
   lons  lats  swch
0   100    80    90
ha.df[:,'lons':'lats']
Traceback (most recent call last):
  File "E:\Anaconda3\envs\tf2\lib\site-packages\IPython\core\interactiveshell.py", line 3417, in run_code
    exec(code_obj, self.user_global_ns, self.user_ns)
  File "<ipython-input-12-8386c1dd40e3>", line 1, in <module>
    ha.df[:,'lons':'lats']
  File "E:\Anaconda3\envs\tf2\lib\site-packages\pandas\core\frame.py", line 2902, in __getitem__
    indexer = self.columns.get_loc(key)
  File "E:\Anaconda3\envs\tf2\lib\site-packages\pandas\core\indexes\base.py", line 2891, in get_loc
    return self._engine.get_loc(casted_key)
  File "pandas\_libs\index.pyx", line 70, in pandas._libs.index.IndexEngine.get_loc
  File "pandas\_libs\index.pyx", line 75, in pandas._libs.index.IndexEngine.get_loc
TypeError: '(slice(None, None, None), slice('lons', 'lats', None))' is an invalid key
ha.df[1:,'lons':'lats']
Traceback (most recent call last):
  File "E:\Anaconda3\envs\tf2\lib\site-packages\IPython\core\interactiveshell.py", line 3417, in run_code
    exec(code_obj, self.user_global_ns, self.user_ns)
  File "<ipython-input-13-c48a9155d545>", line 1, in <module>
    ha.df[1:,'lons':'lats']
  File "E:\Anaconda3\envs\tf2\lib\site-packages\pandas\core\frame.py", line 2902, in __getitem__
    indexer = self.columns.get_loc(key)
  File "E:\Anaconda3\envs\tf2\lib\site-packages\pandas\core\indexes\base.py", line 2891, in get_loc
    return self._engine.get_loc(casted_key)
  File "pandas\_libs\index.pyx", line 70, in pandas._libs.index.IndexEngine.get_loc
  File "pandas\_libs\index.pyx", line 75, in pandas._libs.index.IndexEngine.get_loc
TypeError: '(slice(1, None, None), slice('lons', 'lats', None))' is an invalid key
ha.loc[1:,'lons':'lats']
Traceback (most recent call last):
  File "E:\Anaconda3\envs\tf2\lib\site-packages\IPython\core\interactiveshell.py", line 3417, in run_code
    exec(code_obj, self.user_global_ns, self.user_ns)
  File "<ipython-input-14-bab6bdb78d79>", line 1, in <module>
    ha.loc[1:,'lons':'lats']
AttributeError: module 'hhaa' has no attribute 'loc'
ha.loc[:,'lons':'lats']
Traceback (most recent call last):
  File "E:\Anaconda3\envs\tf2\lib\site-packages\IPython\core\interactiveshell.py", line 3417, in run_code
    exec(code_obj, self.user_global_ns, self.user_ns)
  File "<ipython-input-15-c4fa30fa3fd3>", line 1, in <module>
    ha.loc[:,'lons':'lats']
AttributeError: module 'hhaa' has no attribute 'loc'
ha.df.loc[:,'lons':'lats']
Out[16]:
   lons  lats
0   100    80
1    10    20
2     1     1
ha.df[0]
Traceback (most recent call last):
  File "E:\Anaconda3\envs\tf2\lib\site-packages\pandas\core\indexes\base.py", line 2891, in get_loc
    return self._engine.get_loc(casted_key)
  File "pandas\_libs\index.pyx", line 70, in pandas._libs.index.IndexEngine.get_loc
  File "pandas\_libs\index.pyx", line 101, in pandas._libs.index.IndexEngine.get_loc
  File "pandas\_libs\hashtable_class_helper.pxi", line 1675, in pandas._libs.hashtable.PyObjectHashTable.get_item
  File "pandas\_libs\hashtable_class_helper.pxi", line 1683, in pandas._libs.hashtable.PyObjectHashTable.get_item
KeyError: 0
The above exception was the direct cause of the following exception:
Traceback (most recent call last):
  File "E:\Anaconda3\envs\tf2\lib\site-packages\IPython\core\interactiveshell.py", line 3417, in run_code
    exec(code_obj, self.user_global_ns, self.user_ns)
  File "<ipython-input-17-7fca7b880903>", line 1, in <module>
    ha.df[0]
  File "E:\Anaconda3\envs\tf2\lib\site-packages\pandas\core\frame.py", line 2902, in __getitem__
    indexer = self.columns.get_loc(key)
  File "E:\Anaconda3\envs\tf2\lib\site-packages\pandas\core\indexes\base.py", line 2893, in get_loc
    raise KeyError(key) from err
KeyError: 0
ha.df[1]
Traceback (most recent call last):
  File "E:\Anaconda3\envs\tf2\lib\site-packages\pandas\core\indexes\base.py", line 2891, in get_loc
    return self._engine.get_loc(casted_key)
  File "pandas\_libs\index.pyx", line 70, in pandas._libs.index.IndexEngine.get_loc
  File "pandas\_libs\index.pyx", line 101, in pandas._libs.index.IndexEngine.get_loc
  File "pandas\_libs\hashtable_class_helper.pxi", line 1675, in pandas._libs.hashtable.PyObjectHashTable.get_item
  File "pandas\_libs\hashtable_class_helper.pxi", line 1683, in pandas._libs.hashtable.PyObjectHashTable.get_item
KeyError: 1
The above exception was the direct cause of the following exception:
Traceback (most recent call last):
  File "E:\Anaconda3\envs\tf2\lib\site-packages\IPython\core\interactiveshell.py", line 3417, in run_code
    exec(code_obj, self.user_global_ns, self.user_ns)
  File "<ipython-input-18-3212b4836924>", line 1, in <module>
    ha.df[1]
  File "E:\Anaconda3\envs\tf2\lib\site-packages\pandas\core\frame.py", line 2902, in __getitem__
    indexer = self.columns.get_loc(key)
  File "E:\Anaconda3\envs\tf2\lib\site-packages\pandas\core\indexes\base.py", line 2893, in get_loc
    raise KeyError(key) from err
KeyError: 1
ha.df.loc[0]
Out[19]:
lons    100
lats     80
swch     90
Name: 0, dtype: int64
ha.df.loc[3]
Traceback (most recent call last):
  File "E:\Anaconda3\envs\tf2\lib\site-packages\pandas\core\indexes\range.py", line 355, in get_loc
    return self._range.index(new_key)
ValueError: 3 is not in range
The above exception was the direct cause of the following exception:
Traceback (most recent call last):
  File "E:\Anaconda3\envs\tf2\lib\site-packages\IPython\core\interactiveshell.py", line 3417, in run_code
    exec(code_obj, self.user_global_ns, self.user_ns)
  File "<ipython-input-20-5244a6cc507d>", line 1, in <module>
    ha.df.loc[3]
  File "E:\Anaconda3\envs\tf2\lib\site-packages\pandas\core\indexing.py", line 879, in __getitem__
    return self._getitem_axis(maybe_callable, axis=axis)
  File "E:\Anaconda3\envs\tf2\lib\site-packages\pandas\core\indexing.py", line 1110, in _getitem_axis
    return self._get_label(key, axis=axis)
  File "E:\Anaconda3\envs\tf2\lib\site-packages\pandas\core\indexing.py", line 1059, in _get_label
    return self.obj.xs(label, axis=axis)
  File "E:\Anaconda3\envs\tf2\lib\site-packages\pandas\core\generic.py", line 3488, in xs
    loc = self.index.get_loc(key)
  File "E:\Anaconda3\envs\tf2\lib\site-packages\pandas\core\indexes\range.py", line 357, in get_loc
    raise KeyError(key) from err
KeyError: 3
ha.df.loc[3] = [80,20,30]
ha.df
Out[22]:
   lons  lats  swch
0   100    80    90
1    10    20    95
2     1     1    96
3    80    20    30
ha.df.loc(4)=[100,80,90]
  File "<ipython-input-23-caf4c0df73b1>", line 1
    ha.df.loc(4)=[100,80,90]
    ^
SyntaxError: cannot assign to function call
ha.df.loc[4] = [80,20,90]
ha.df.sort_values(by=['lons', 'lats'])
Out[25]:
   lons  lats  swch
2     1     1    96
1    10    20    95
3    80    20    30
4    80    20    90
0   100    80    90
for i in ha.df:
   ...:     print(i)
   ...:
lons
lats
swch
for i in ha.df.T:
   ...:     print(i)
   ...:
0
1
2
3
4
for index, row in ha.df.itertuples():
   ...:     print(row)
   ...:
Traceback (most recent call last):
  File "E:\Anaconda3\envs\tf2\lib\site-packages\IPython\core\interactiveshell.py", line 3417, in run_code
    exec(code_obj, self.user_global_ns, self.user_ns)
  File "<ipython-input-28-8ca52230dc5c>", line 1, in <module>
    for index, row in ha.df.itertuples():
ValueError: too many values to unpack (expected 2)
for row in ha.df.itertuples():
   ...:     print(getattr(row,'lons'), getattr(row, 'lats'))
   ...:
100 80
10 20
1 1
80 20
80 20
hasort = ha.df.sort_values(by=['lons', 'lats'])
for row in hasort.df.itertuples():
   ...:     print(getattr(row,'lons'), getattr(row, 'lats'))
   ...:
Traceback (most recent call last):
  File "E:\Anaconda3\envs\tf2\lib\site-packages\IPython\core\interactiveshell.py", line 3417, in run_code
    exec(code_obj, self.user_global_ns, self.user_ns)
  File "<ipython-input-31-3e79b0b46069>", line 1, in <module>
    for row in hasort.df.itertuples():
  File "E:\Anaconda3\envs\tf2\lib\site-packages\pandas\core\generic.py", line 5136, in __getattr__
    return object.__getattribute__(self, name)
AttributeError: 'DataFrame' object has no attribute 'df'
for row in hasort.itertuples():
   ...:     print(getattr(row,'lons'), getattr(row, 'lats'))
   ...:
1 1
10 20
80 20
80 20
100 80
for row in hasort.itertuples():
   ...:     print(getattr(row,'lons'), getattr(row, 'lats'))
   ...:
1 1
10 20
80 20
80 20
100 80
temp_lon,temp_lat = 0
Traceback (most recent call last):
  File "E:\Anaconda3\envs\tf2\lib\site-packages\IPython\core\interactiveshell.py", line 3417, in run_code
    exec(code_obj, self.user_global_ns, self.user_ns)
  File "<ipython-input-34-5ddf230521c8>", line 1, in <module>
    temp_lon,temp_lat = 0
TypeError: cannot unpack non-iterable int object
temp_lon,temp_lat = 0,0
for row in hasort.itertuples():
   ...:     print(getattr(row,'lons'), getattr(row, 'lats'))
   ...:     if (getattr(row,'lons'), getattr(row, 'lats')==temp_lon, temp_lat):
   ...:         hasort['swhc']=1
   ...:     temp_lon, temp_lat = getattr(row,'lons'),getattr(row,'lats')
   ...:
1 1
10 20
80 20
80 20
100 80
hasort
Out[37]:
   lons  lats  swch  swhc
2     1     1    96     1
1    10    20    95     1
3    80    20    30     1
4    80    20    90     1
0   100    80    90     1
for row in hasort.itertuples():
   ...:     print(getattr(row,'lons'), getattr(row, 'lats'))
   ...:     if ((getattr(row,'lons')==temp_lon)&( getattr(row, 'lats')==temp_lat)):
   ...:         hasort['swhc']=1
   ...:     temp_lon, temp_lat = getattr(row,'lons'),getattr(row,'lats')
   ...:
1 1
10 20
80 20
80 20
100 80
hasort
Out[39]:
   lons  lats  swch  swhc
2     1     1    96     1
1    10    20    95     1
3    80    20    30     1
4    80    20    90     1
0   100    80    90     1
for row in hasort.itertuples():
   ...:     print(getattr(row,'lons'), getattr(row, 'lats'))
   ...:     if ((getattr(row,'lons')==temp_lon)&( getattr(row, 'lats')==temp_lat)):
   ...:         hasort['swhc']=1
   ...:     temp_lon, temp_lat = getattr(row,'lons'),getattr(row,'lats')
   ...:     print(temp_lon, temp_lat)
   ...:
1 1
1 1
10 20
10 20
80 20
80 20
80 20
80 20
100 80
100 80
for row in hasort.itertuples():
   ...:     print(getattr(row,'lons'), getattr(row, 'lats'))
   ...:     if ((getattr(row,'lons')==temp_lon)and( getattr(row, 'lats')==temp_lat)):
   ...:         hasort['swhc']=1
   ...:     temp_lon, temp_lat = getattr(row,'lons'),getattr(row,'lats')
   ...:     print(temp_lon, temp_lat)
   ...:
1 1
1 1
10 20
10 20
80 20
80 20
80 20
80 20
100 80
100 80
hasort
Out[42]:
   lons  lats  swch  swhc
2     1     1    96     1
1    10    20    95     1
3    80    20    30     1
4    80    20    90     1
0   100    80    90     1
